Workbook

Sheet Article Master
A1: Desc | B1: Description | C1: Product | D1: Price
A2: Sandpaper-WABRPAP-(SILIC-CA)-WTRPROF-P1500-230X280 | B2: WABRPAP-(SILIC-CA)-WTRPROF-P1500-230X280 | C2: 0584111500 | D2: 37
A3: Sandpaper sheet wet-P2000-230X280 | B3: WSPAP-(SILIC-CA)-WTRPROF-P2000-230X280 | C3: 0584112000 | D3: 37
A4: Polishing pad-GREEN-(EXTRA-HARD)-D145X25MM | B4: POLPAD-GREEN-(EXTRA-HARD)-D145X25MM | C4: 0585025145 | D4: 1013.25
A5: Polishing pad-GREEN-(EXTRA-HARD)-D170X25MM | B5: POLPAD-GREEN-(EXTRA-HARD)-D170X25MM | C5: 0585025170 | D5: 2057.92
A6: Polishing pad-ORANGE-SOFT-D145X25MM | B6: POLPAD-ORANGE-SOFT-D145X25MM | C6: 0585026145 | D6: 942.75
A7: Polishing pad-ORANGE-SOFT-D170X30MM | B7: POLPAD-ORANGE-SOFT-D170X30MM | C7: 0585026170 | D7: 2053.33
A8: Polishing pad-BLUE-HARD-D90X25MM | B8: POLPAD-BLUE-HARD-D90X25MM | C8: 0585027090961 4 | D8: 437.25
A9: Polishing pad-BLUE-HARD-D145X25MM | B9: POLPAD-BLUE-HARD-D145X25MM | C9: 0585027145 | D9: 930
A10: Polishing pad-BLUE-HARD-D170X30MM | B10: POLPAD-BLUE-HARD-D170X30MM | C10: 0585027170 | D10: 2103.75
A11: Polishing pad | B11: POLSPNG-D200X30 | C11: 058520030 | D11: 750
A12: Sanding pad-GREY-G1500 | B12: SANDSPNG-(ALU-OXYD)-GREY-G1500 | C12: 0587004 | D12: 75
A13: FLEXHOSE-F.VC-0702400801/02/03-38MMX2M | B13: FLEXHOSE-F.VC-0702400801/02/03-38MMX2M | C13: 0702991338 | D13: 3291.2
... A120: PREMIUM SEAT COVER SET | B120: PREMIUM SEAT COVER SET | C120: NDI0000327990 1 | D120: 61

Sheet Sheet1
A1: CERAMIC COATING | B1: WNDWPROTFOIL-BLCK-VLT75PERCNT-2PLY-100FT | C1: WSCRNCLNR-ACTIVE-500ML | D1: MICROCLTH-BLUE-40X40CM | E1: RUBBING & FINISING COMPOUND 1KG | F1: SILSPR-500ML | G1: CLNR-VEH-IN-ACTIVE-500ML | H1: MARTENPROTSPR-250ML | I1: POL-NEWPAINT-1LTR | J1: UBS-PERMANENT-SPRAYABLE-BLACK-1000ML | K1: A/C-CLNR-VEH-QUICKFRESH-FRESH-150ML | L1: PLACARE-VINYL-1LTR | M1: WRKSHPCLNR-BMF-TROPIC-5LTR | N1: POLSHR-EL-(EPM 2000-7)-1200W | O1: WNDWPROTFOIL-BLCK-VLT50PERCNT-2PLY-100FT | P1: WUERTH CAR CLEANER 5 LTR | Q1: WOOL GRIP PAD | R1: SOFT BRUSH | S1: UNDERB BODY SEAL 10 LTR | T1: CAVWAX-BEIGE-1000ML | U1: CAVWAX-BEIGE-500ML | V1: BTRYTRMLGRSE-PROTECTOR-150ML | W1: POL-PAINTRESTORATION-1LTR | X1: ZNSPR-ZINCGREY-400ML | Y1: STNIMPPROT-UBS-BLACK-1000ML | Z1: PAINT SPRAY-HIGHTEMP-ALUMINIUM-300ML | AA1: FOAM PAD YELLOW | AB1: TREGLO-MILKYWHITE-5LTR | AC1: WU CAR SHAMPOO 35 LTR. | AD1: ADHLUB-HHS2000-500ML | AE1: RUSTREM-300G | AF1: POL-DIAMOND-CUT-PREMIUM-1LTR | AG1: WUERTH CAR CLEANER 1 LTR | AH1: ENGPROTLAC-400ML | AI1: POLCOMPD-210G | AJ1: LACWRKSEAL-GLOSS-250ML | AK1: RIMCLNR-INTENSIVE-SPRAYBOTTLE-1LTR | AL1: ALUSPR-PERFECT-400ML | AM1: PMPSPRBTL-PLA-EMPTY-1LTR | AN1: CLNR-VEH-CHERRY-1LTR | AO1: CLNR-VEH-CHERRY-5LTR | AP1: PROTECTIVE SILENCER COATING 500ML | AQ1: ENGCLNR-ENGINEWASH-5LTR | AR1: SOUADSORBPLT-ALU-GREY-550X250X2-6PCS | AS1: TREGLO-MILKYWHITE-30LTR | AT1: POL-(HIGHGLOSS PLUS)-P20-1KG | AU1: POL-(ANTIHOLOGRAMM PLUS)-P30-1KG | AV1: POL-(FASTCUT PLUS)-P10-1KG | AW1: POLPAD-GREEN-(EXTRA-HARD)-D170X25MM | AX1: POLPAD-BLUE-HARD-D170X30MM | AY1: POLPAD-ORANGE-SOFT-D170X30MM | AZ1: MICROCLTH-PESFBR-YELLOW-107C-40X40CM | BA1: CLNR-VEH-IN-BEIGE-5LTR | BB1: PLACARE-VINYL-5LTR | BC1: CLNAGNT-A/C EVAPORATOR-PURIFY-250ML | BD1: AC FOAM CLEANER | BE1: MULTIPURPOSE CLEANER 500 ML | BF1: CLNAGNT-A/C-CAR-300ML | BG1: SANDSPNG-(ALU-OXYD)-GREY-G1500 | BH1: WSPAP-(SILIC-CA)-WTRPROF-P2000-230X280 | BI1: CLNR-VEH-IN-BEIGE-1LTR | BJ1: NPL-NIPL-1/4ET | BK1: 157MM SUPPORT PAD FOR VC FOAM - CUPPED W | BL1: UBSSPRGUN-R1/4IN-BOTTLE-1LTR | BM1: PROTGLOV-SPEC-COTTON-B40-G7-SZ9-GREY | BN1: CLNGUN-PN-ENGCLNR-750ML | BO1: GLASS CLEANER 500 ML | BP1: LBLREM-(INDUSTRY-CLEANER)-AEROCAN-500ML | BQ1: METRSTRR-400G | BR1: RIMCLNR-ALU-SPRAYBOTTLE-500ML | BS1: CLNSPNG-CAR | BT1: POLSPNG-D200X30 | BU1: POLPAD-GREEN-(EXTRA-HARD)-D145X25MM | BV1: POLPAD-ORANGE-SOFT-D145X25MM | BW1: POLPAD-BLUE-HARD-D145X25MM | BX1: POL-(ANTIHOLOGRAMM PLUS)-P30-250G | BY1: WABRPAP-(SILIC-CA)-WTRPROF-P1500-230X280 | BZ1: TARREM-300ML | CA1: UNDERBBODY SEAL 20L | CB1: MICROQUICK BLUE - 40X40 CM MICROFIBRE WI | CC1: RUBBING AND COMPOUNDING PAD DIA 200MM | CD1: PROTGLOV-CHEM-NTR-330MM-SZ10 | CE1: PAINT POLISH 1LTR | CF1: RDBRSH-VC-38MM-702400801/02/03 | CG1: ADHLUB-500ML | CH1: FLEXHOSE-F.VC-0702400801/02/03-38MMX2M | CI1: MASKTPE-CREPE-24MMX30M | CJ1: MASKTPE-CREPE-WHITE/BROWN-24MMX50M | CK1: BACKUP PLATE | CL1: TRECAREFM-500ML | CM1: ZNSPR-PERFECT-400ML | CN1: AY-SPRAYPIPE-SYSCLNR-VEH | CO1: MICROCLTH-BASIC-GREEN-40X40CM | CP1: DSTCLTH-32X100CM | CQ1: VACCUM CLEANER 32 LTR | CR1: CLNR-WSCRN-SUM-RAPID-CONC-32ML | CS1: SPRBTL-SCAL-1000ML | CT1: GLSCLNR-5LTR | CU1: POL-(LIQUID-WAX)-BEIGE-100ML | CV1: FOAM PAD BLACK | CW1: POL-(EXTREME CUT)-AP05-1LTR | CX1: 3 PLY MASK – MELTBLOWN FILTER ELST
A2: 5997600792 | B2: 09929208 | C2: 089025 | D2: 0899900117 | E2: 5997655753 | F2: 0893221525 | G2: 0893033 | H2: 0892077150 | I2: 0893152001 | J2: 0892072 | K2: 0893764158 | L2: 0893477121 | M2: 0893118825 | N2: 5717010010 | O2: 09929207 | P2: NDI0000131 | Q2: NDI0000196 | R2: 5997580621 | S2: 5997633518 | T2: 0892082100 | U2: 0892082105 | V2: 0890104 | W2: 0893151101 | X2: 0893113120 | Y2: 0892075200 | Z2: 0893012026 | AA2: NDI0000188 | AB2: 089012 505 | AC2: NDI0000091 | AD2: 0893106 | AE2: 0890200011 | AF2: 0893463001 | AG2: NDI0000132 | AH2: 0892790 | AI2: 08931571 | AJ2: 08930126 | AK2: 0893476 | AL2: 0893114115 | AM2: 0891503001 | AN2: 0893022002 | AO2: 0893022003 | AP2: 5997661621 | AQ2: 089301305 | AR2: 0890100060 | AS2: 089012 035 | AT2: 0893150020 | AU2: 0893150030 | AV2: 0893150010 | AW2: 0585025170 | AX2: 0585027170 | AY2: 0585026170 | AZ2: 0899900119 | BA2: 089347425 | BB2: 0893477125 | BC2: 0893764003 | BD2: 5997661901 | BE2: NDI0000101 | BF2: 0893764310 | BG2: 0587004 | BH2: 0584112000 | BI2: 089347421 | BJ2: 0699999000 | BK2: NDI0000264 | BL2: 08911063 | BM2: 089940407 | BN2: 0891612 | BO2: NDI0000103 | BP2: 0893140 | BQ2: 08931211 | BR2: 0890102 | BS2: 0899700400 | BT2: 058520030 | BU2: 0585025145 | BV2: 0585026145 | BW2: 0585027145 | BX2: 0893150032 | BY2: 0584111500 | BZ2: 089026 | CA2: 5997592160 | CB2: 5997638643 | CC2: NDI0000271 | CD2: 089943510 | CE2: 5997661902 | CF2: 0702991343 | CG2: 089310652 | CH2: 0702991338 | CI2: 0992068024 | CJ2: 0992068025 | CK2: NDI0000198 | CL2: 0890121525 | CM2: 0893114113 | CN2: 0891564 | CO2: 0899900050 | CP2: 0899700005 | CQ2: 5997623023 | CR2: 0892333032 | CS2: 0891502003 | CT2: 08902205 | CU2: 089310004 | CV2: NDI0000187 | CW2: 0893469105 | CX2: 5997638386

Sheet Work Sheet
B1: ADM Name: | D1: Order Number
B2: Rep Code: | D2: Total Value | G2: =SUMPRODUCT($E$6:$E$84,G6:G84) -> 0 | H2: =SUMPRODUCT($E$6:$E$84,H6:H84) -> 0 | I2: =SUMPRODUCT($E$6:$E$84,I6:I84) -> 0 | J2: =SUMPRODUCT($E$6:$E$84,J6:J84) -> 1805 | K2: =SUMPRODUCT($E$6:$E$84,K6:K84) -> 800 | L2: =SUMPRODUCT($E$6:$E$84,L6:L84) -> 1805 | M2: =SUMPRODUCT($E$6:$E$84,M6:M84) -> 6110 | N2: =SUMPRODUCT($E$6:$E$84,N6:N84) -> 0 | ... BF2: =SUMPRODUCT($E$6:$E$84,BF6:BF84) -> 0
J3: KVR DREAM VEHICLE PVT. LTD. | K3: CARZONE | L3: KVR DREAM VEHICLE PVT. LTD. | M3: HYSON MOTORS | N3: HYSON MOTORS | O3: HYSON MOTORS | P3: HYSON MOTORS | Q3: PHOENIX CAR INDIA PVT. LTD | R3: PHOENIX CAR INDIA PVT. LTD | S3: Customer Name | T3: Customer Name | U3: Customer Name | V3: Customer Name | W3: Customer Name | X3: Customer Name | Y3: Customer Name | Z3: Customer Name | AA3: Customer Name | AB3: Customer Name | AC3: Customer Name | AD3: Customer Name | AE3: Customer Name | AF3: Customer Name | AG3: Customer Name | AH3: Customer Name | AI3: Customer Name | AJ3: Customer Name | AK3: Customer Name | AL3: Customer Name | AM3: Customer Name | AN3: Customer Name | AO3: Customer Name | AP3: Customer Name | AQ3: Customer Name | AR3: Customer Name | AS3: Customer Name | AT3: Customer Name | AU3: Customer Name | AV3: Customer Name | AW3: Customer Name | AX3: Customer Name | AY3: Customer Name | AZ3: Customer Name | BA3: Customer Name | BB3: Customer Name | BC3: Customer Name | BD3: Customer Name | BE3: Customer Name | BF3: Customer Name
A4: Remarks | B4: Sl.No: | C4: SAP ITEM NAME | D4: Article Number | E4: Price | F4: PRS | J4: KVR DREAM VEHICLE PVT. LTD PANALAM NAIMARMOOLA POST CHENGALA ,KASARAGOD 671123 | K4: 71/1739B,ATHANIKKAL,KANNUR ROAD,KOZHIKODE,KERALA,673005 | L4: KVR DREAM VEHICLE PVT. LTD KANDOTH ,OPP BHARATH PETROLPUMP PAYYANNUR 670307 KANNUR - DTS | M4: HYSON MOTORS, PUZHAKKAL PADAM, GURUVAYUR ROAD, THRISSUR - 680002 | N4: HYSON MOTORS PVT LTD - GURUVAYOOR OPP:CHOOLPURAM MUSJID, KOTTAPADY.P.O 680505 GURUVAYOOR-THRISSUR Kerala | O4: HYSON MOTORS PVT LTD. PANAMPALLY COLLEGE, POTTA, CHALAKKUDY -680307 | P4: HYSON MOTORS- KODUNGALLUR T K S PURAM OPP.MEDICARE HOSPITAL 680664 KODUNGALLUR-THRISSUR Kerala State Code- 32 | Q4: PHOENIX CAR INDIA PVT. LTD. - PKD Near Asianet Office, Matha Kovil Street, Sulthanpet, Palakkad | R4: PHOENIX CAR INDIA PVT. LTD. - TCR 12/493/1, N.H 47 MANNUTHY BYE PASS 687051 TRISSUR-TRISSUR | S4: Delivery Address (If any) | T4: Delivery Address (If any) | U4: Delivery Address (If any) | V4: Delivery Address (If any) | W4: Delivery Address (If any) | X4: Delivery Address (If any) | Y4: Delivery Address (If any) | Z4: Delivery Address (If any) | AA4: Delivery Address (If any) | AB4: Delivery Address (If any) | AC4: Delivery Address (If any) | AD4: Delivery Address (If any) | AE4: Delivery Address (If any) | AF4: Delivery Address (If any) | AG4: Delivery Address (If any) | AH4: Delivery Address (If any) | AI4: Delivery Address (If any) | AJ4: Delivery Address (If any) | AK4: Delivery Address (If any) | AL4: Delivery Address (If any) | AM4: Delivery Address (If any) | AN4: Delivery Address (If any) | AO4: Delivery Address (If any) | AP4: Delivery Address (If any) | AQ4: Delivery Address (If any) | AR4: Delivery Address (If any) | AS4: Delivery Address (If any) | AT4: Delivery Address (If any) | AU4: Delivery Address (If any) | AV4: Delivery Address (If any) | AW4: Delivery Address (If any) | AX4: Delivery Address (If any) | AY4: Delivery Address (If any) | AZ4: Delivery Address (If any) | BA4: Delivery Address (If any) | BB4: Delivery Address (If any) | BC4: Delivery Address (If any) | BD4: Delivery Address (If any) | BE4: Delivery Address (If any) | BF4: Delivery Address (If any)
J5: 157128653 | K5: 157138368 | L5: 157128652 | M5: 157092027 | N5: 157091842 | O5: 157092028 | P5: 157092029 | Q5: 157091840 | R5: 157091840 | S5: Customer Code | T5: Customer Code | U5: Customer Code | V5: Customer Code | W5: Customer Code | X5: Customer Code | Y5: Customer Code | Z5: Customer Code | AA5: Customer Code | AB5: Customer Code | AC5: Customer Code | AD5: Customer Code | AE5: Customer Code | AF5: Customer Code | AG5: Customer Code | AH5: Customer Code | AI5: Customer Code | AJ5: Customer Code | AK5: Customer Code | AL5: Customer Code | AM5: Customer Code | AN5: Customer Code | AO5: Customer Code | AP5: Customer Code | AQ5: Customer Code | AR5: Customer Code | AS5: Customer Code | AT5: Customer Code | AU5: Customer Code | AV5: Customer Code | AW5: Customer Code | AX5: Customer Code | AY5: Customer Code | AZ5: Customer Code | BA5: Customer Code | BB5: Customer Code | BC5: Customer Code | BD5: Customer Code | BE5: Customer Code | BF5: Customer Code
B6: 1 | C6: Remover of tar | D6: =IFERROR(VLOOKUP(C6,'Article Master'!A:C,3,0),"") -> 089026 | E6: =IFERROR(VLOOKUP(C6,'Article Master'!A:D,4,0),"") -> 925.83 | F6: 0
B7: 2 | C7: Underbody seal-SPRAYABLE-BLACK-1000ML | D7: =IFERROR(VLOOKUP(C7,'Article Master'!A:C,3,0),"") -> 0892072 | E7: =IFERROR(VLOOKUP(C7,'Article Master'!A:D,4,0),"") -> 750 | F7: 0 | M7: 2
B8: 3 | C8: Stone impact protection-BLACK-1000ML | D8: =IFERROR(VLOOKUP(C8,'Article Master'!A:C,3,0),"") -> 0892075200 | E8: =IFERROR(VLOOKUP(C8,'Article Master'!A:D,4,0),"") -> 900 | F8: 0 | M8: 2
B9: 4 | C9: PAINTRESTORATION-1LTR | D9: =IFERROR(VLOOKUP(C9,'Article Master'!A:C,3,0),"") -> 0893151101 | E9: =IFERROR(VLOOKUP(C9,'Article Master'!A:D,4,0),"") -> 1000 | F9: 0
B10: 5 | C10: Spray gun, underbody seal-BOTTLE-1LTR | D10: =IFERROR(VLOOKUP(C10,'Article Master'!A:C,3,0),"") -> 08911063 | E10: =IFERROR(VLOOKUP(C10,'Article Master'!A:D,4,0),"") -> 4250 | F10: 0
B11: 6 | C11: NEWPAINTPOLISH-1LTR | D11: =IFERROR(VLOOKUP(C11,'Article Master'!A:C,3,0),"") -> 0893152001 | E11: =IFERROR(VLOOKUP(C11,'Article Master'!A:D,4,0),"") -> 1000 | F11: 0
B12: 7 | C12: DIAMOND-CUT-PREMIUM-1LTR | D12: =IFERROR(VLOOKUP(C12,'Article Master'!A:C,3,0),"") -> 0893463001 | E12: =IFERROR(VLOOKUP(C12,'Article Master'!A:D,4,0),"") -> 1250 | F12: 0
B13: 8 | C13: Plastic-care, vehicle | D13: =IFERROR(VLOOKUP(C13,'Article Master'!A:C,3,0),"") -> 0893221525 | E13: =IFERROR(VLOOKUP(C13,'Article Master'!A:D,4,0),"") -> 255 | F13: 0
B14: 9 | C14: Masking crepe tape-MASKTPE-CREPE-24MMX30M | D14: =IFERROR(VLOOKUP(C14,'Article Master'!A:C,3,0),"") -> 0992068024 | E14: =IFERROR(VLOOKUP(C14,'Article Master'!A:D,4,0),"") -> 40 | F14: 0
B15: 10 | C15: Multipurpose Vinyl Care - 1Ltr | D15: =IFERROR(VLOOKUP(C15,'Article Master'!A:C,3,0),"") -> 0893477121 | E15: =IFERROR(VLOOKUP(C15,'Article Master'!A:D,4,0),"") -> 400 | F15: 0
B16: 11 | C16: WOOL GRIP PAD | D16: =IFERROR(VLOOKUP(C16,'Article Master'!A:C,3,0),"") -> NDI0000196 | E16: =IFERROR(VLOOKUP(C16,'Article Master'!A:D,4,0),"") -> 1085 | F16: 0
B17: 12 | C17: Cleaner for vehicle interior-ACTIVE-500ML | D17: =IFERROR(VLOOKUP(C17,'Article Master'!A:C,3,0),"") -> 0893033 | E17: =IFERROR(VLOOKUP(C17,'Article Master'!A:D,4,0),"") -> 465 | F17: 0
B18: 13 | C18: Interior Cleaner - 1Ltr | D18: =IFERROR(VLOOKUP(C18,'Article Master'!A:C,3,0),"") -> 089347421 | E18: =IFERROR(VLOOKUP(C18,'Article Master'!A:D,4,0),"") -> 335 | F18: 0
B19: 14 | C19: GLASS CLEANER 500 ML | D19: =IFERROR(VLOOKUP(C19,'Article Master'!A:C,3,0),"") -> NDI0000103 | E19: =IFERROR(VLOOKUP(C19,'Article Master'!A:D,4,0),"") -> 174.75 | F19: 0
B20: 15 | C20: AC FOAM CLEANER | D20: =IFERROR(VLOOKUP(C20,'Article Master'!A:C,3,0),"") -> 5997661901 | E20: =IFERROR(VLOOKUP(C20,'Article Master'!A:D,4,0),"") -> 250 | F20: 0
... B50: 45 | C50: WRKSHPCLNR-BMF-TROPIC-5LTR | D50: =IFERROR(VLOOKUP(C50,'Article Master'!A:C,3,0),"") -> 0893118825 | E50: =IFERROR(VLOOKUP(C50,'Article Master'!A:D,4,0),"") -> 2499 | F50: 0
B51: 46 | C51: Insect and animal repellent | D51: =IFERROR(VLOOKUP(C51,'Article Master'!A:C,3,0),"") -> 0892077150 | E51: =IFERROR(VLOOKUP(C51,'Article Master'!A:D,4,0),"") -> 800 | F51: 0 | J51: 1 | K51: 1 | L51: 1 | M51: 1 | O51: 1
B52: 47 | C52: Polishing machine, electric-1200W | D52: =IFERROR(VLOOKUP(C52,'Article Master'!A:C,3,0),"") -> 5717010010 | E52: =IFERROR(VLOOKUP(C52,'Article Master'!A:D,4,0),"") -> 18000 | F52: 0
B53: 48 | C53: Micro-fibre cloth | D53: =IFERROR(VLOOKUP(C53,'Article Master'!A:C,3,0),"") -> 0899900050 | E53: =IFERROR(VLOOKUP(C53,'Article Master'!A:D,4,0),"") -> 149 | F53: 0
B54: 49 | C54: CERAMIC COATING | D54: =IFERROR(VLOOKUP(C54,'Article Master'!A:C,3,0),"") -> 5997600792 | E54: =IFERROR(VLOOKUP(C54,'Article Master'!A:D,4,0),"") -> 12000 | F54: 0
B55: 50 | C55: RUBBING PAD DOUB.SIDE | D55: =IFERROR(VLOOKUP(C55,'Article Master'!A:C,3,0),"") -> NDI0000197990 1 | E55: =IFERROR(VLOOKUP(C55,'Article Master'!A:D,4,0),"") -> 2000.05 | F55: 0
B56: 51 | C56: WUERTH CAR CLEANER 1 LTR | D56: =IFERROR(VLOOKUP(C56,'Article Master'!A:C,3,0),"") -> NDI0000132 | E56: =IFERROR(VLOOKUP(C56,'Article Master'!A:D,4,0),"") -> 175 | F56: 0
B57: 52 | C57: Spray gun, underbody seal-BOTTLE-1LTR | D57: =IFERROR(VLOOKUP(C57,'Article Master'!A:C,3,0),"") -> 08911063 | E57: =IFERROR(VLOOKUP(C57,'Article Master'!A:D,4,0),"") -> 4250 | F57: 0
B58: 53 | C58: Cleaner for glass-5LTR | D58: =IFERROR(VLOOKUP(C58,'Article Master'!A:C,3,0),"") -> 08902205 | E58: =IFERROR(VLOOKUP(C58,'Article Master'!A:D,4,0),"") -> 1500.25 | F58: 0
B59: 54 | C59: Cleaning sponge | D59: =IFERROR(VLOOKUP(C59,'Article Master'!A:C,3,0),"") -> 0899700400 | E59: =IFERROR(VLOOKUP(C59,'Article Master'!A:D,4,0),"") -> 194.37 | F59: 0
B60: 55 | C60: Pump spray bottle | D60: =IFERROR(VLOOKUP(C60,'Article Master'!A:C,3,0),"") -> 0891503001 | E60: =IFERROR(VLOOKUP(C60,'Article Master'!A:D,4,0),"") -> 2954.05 | F60: 0
B61: 56 | C61: MICROQUICK BLUE - 40X40 CM MICROFIBRE WI | D61: =IFERROR(VLOOKUP(C61,'Article Master'!A:C,3,0),"") -> 5997638643 | E61: =IFERROR(VLOOKUP(C61,'Article Master'!A:D,4,0),"") -> 206.25 | F61: 0
B62: 57 | C62: Battery terminal maintenance | D62: =IFERROR(VLOOKUP(C62,'Article Master'!A:C,3,0),"") -> 0890104 | E62: =IFERROR(VLOOKUP(C62,'Article Master'!A:D,4,0),"") -> 355 | F62: 0 | J62: 1 | L62: 1 | M62: 2
B63: 58 | C63: ADHLUB-HHS2000-500ML | D63: 0893106 | E63: =IFERROR(VLOOKUP(C63,'Article Master'!A:D,4,0),"") -> 650 | F63: 0 | J63: 1 | L63: 1 | M63: 2
B64: 59 | C64: Tyre gloss-MILKYWHITE--500ML | D64: =IFERROR(VLOOKUP(C64,'Article Master'!A:C,3,0),"") -> 089012 500045 1 | E64: =IFERROR(VLOOKUP(C64,'Article Master'!A:D,4,0),"") -> 350 | F64: 0
B65: 60 | C65: CERAMIC COATING | D65: =IFERROR(VLOOKUP(C65,'Article Master'!A:C,3,0),"") -> 5997600792 | E65: =IFERROR(VLOOKUP(C65,'Article Master'!A:D,4,0),"") -> 12000 | F65: 0
B66: 61 | C66: BACKUP PLATE | D66: =IFERROR(VLOOKUP(C66,'Article Master'!A:C,3,0),"") -> NDI0000198 | E66: =IFERROR(VLOOKUP(C66,'Article Master'!A:D,4,0),"") -> 1500.25 | F66: 0
B67: 62 | C67: CLNAPP-FOAM-GUN-SP1 | D67: =IFERROR(VLOOKUP(C67,'Article Master'!A:C,3,0),"") -> 0891703128961 1 | E67: =IFERROR(VLOOKUP(C67,'Article Master'!A:D,4,0),"") -> 6335 | F67: 0
B68: 63 | D68: =IFERROR(VLOOKUP(C68,'Article Master'!A:C,3,0),"") | E68: =IFERROR(VLOOKUP(C68,'Article Master'!A:D,4,0),"") | F68: 0
B69: 64 | D69: =IFERROR(VLOOKUP(C69,'Article Master'!A:C,3,0),"") | E69: =IFERROR(VLOOKUP(C69,'Article Master'!A:D,4,0),"") | F69: 0
...

Sheet Overall Total Value
F1: KVR DREAM VEHICLE PVT. LTD PANALAM NAIMARMOOLA POST CHENGALA ,KASARAGOD 671123 | G1: 71/1739B,ATHANIKKAL,KANNUR ROAD,KOZHIKODE,KERALA,673005 | H1: KVR DREAM VEHICLE PVT. LTD KANDOTH ,OPP BHARATH PETROLPUMP PAYYANNUR 670307 KANNUR - DTS | I1: HYSON MOTORS, PUZHAKKAL PADAM, GURUVAYUR ROAD, THRISSUR - 680002 | J1: HYSON MOTORS PVT LTD - GURUVAYOOR OPP:CHOOLPURAM MUSJID, KOTTAPADY.P.O 680505 GURUVAYOOR-THRISSUR Kerala | K1: HYSON MOTORS PVT LTD. PANAMPALLY COLLEGE, POTTA, CHALAKKUDY -680307 | L1: HYSON MOTORS- KODUNGALLUR T K S PURAM OPP.MEDICARE HOSPITAL 680664 KODUNGALLUR-THRISSUR Kerala State Code- 32 | M1: PHOENIX CAR INDIA PVT. LTD. - PKD Near Asianet Office, Matha Kovil Street, Sulthanpet, Palakkad | N1: HYSON AUTO SALES PVT LTD - THRISSUR FIAT NH 47, BYPASS 680014 THRISSUR-THRISSUR Kerala | O1: Customer Name | P1: Customer Name | Q1: Customer Name | R1: Customer Name | S1: Customer Name | T1: Customer Name | U1: Customer Name | V1: Customer Name | W1: Customer Name | X1: Customer Name | Y1: Customer Name | Z1: Customer Name | AA1: Customer Name | AB1: Customer Name | AC1: Customer Name | AD1: Customer Name | AE1: Customer Name | AF1: Customer Name | AG1: Customer Name | AH1: Customer Name | AI1: Customer Name | AJ1: Customer Name | AK1: Customer Name | AL1: Customer Name | AM1: Customer Name | AN1: Customer Name | AO1: Customer Name | AP1: Customer Name | AQ1: Customer Name | AR1: Customer Name | AS1: Customer Name | AT1: Customer Name | AU1: Customer Name | AV1: Customer Name | AW1: Customer Name | AX1: Customer Name | AY1: Customer Name | AZ1: Customer Name | BA1: Customer Name
F2: 157128653 | G2: 157138368 | H2: 157128652 | I2: 157092027 | J2: 157091842 | K2: 157092028 | L2: 157092029 | M2: 157091840 | N2: 157091838 | O2: Customer Code | P2: Customer Code | Q2: Customer Code | R2: Customer Code | S2: Customer Code | T2: Customer Code | U2: Customer Code | V2: Customer Code | W2: Customer Code | X2: Customer Code | Y2: Customer Code | Z2: Customer Code | AA2: Customer Code | AB2: Customer Code | AC2: Customer Code | AD2: Customer Code | AE2: Customer Code | AF2: Customer Code | AG2: Customer Code | AH2: Customer Code | AI2: Customer Code | AJ2: Customer Code | AK2: Customer Code | AL2: Customer Code | AM2: Customer Code | AN2: Customer Code | AO2: Customer Code | AP2: Customer Code | AQ2: Customer Code | AR2: Customer Code | AS2: Customer Code | AT2: Customer Code | AU2: Customer Code | AV2: Customer Code | AW2: Customer Code | AX2: Customer Code | AY2: Customer Code | AZ2: Customer Code | BA2: Customer Code
B3: Week 1 | C3: =SUMPRODUCT($E$6:$E$84,C7:C85) -> 0 | D3: =SUMPRODUCT($E$6:$E$84,D7:D85) -> 0 | E3: =SUMPRODUCT($E$6:$E$84,E7:E85) -> 0 | F3: 47139.85 | G3: 29472.98 | H3: 39194.79 | O3: =SUMPRODUCT($E$6:$E$84,O7:O85) -> 0 | P3: =SUMPRODUCT($E$6:$E$84,P7:P85) -> 0 | Q3: =SUMPRODUCT($E$6:$E$84,Q7:Q85) -> 0 | R3: =SUMPRODUCT($E$6:$E$84,R7:R85) -> 0 | S3: =SUMPRODUCT($E$6:$E$84,S7:S85) -> 0 | T3: =SUMPRODUCT($E$6:$E$84,T7:T85) -> 0 | U3: =SUMPRODUCT($E$6:$E$84,U7:U85) -> 0 | V3: =SUMPRODUCT($E$6:$E$84,V7:V85) -> 0 | W3: 0
B4: Week 2 | P4: 0
B5: Week 3
B6: Week 4
B7: Week 5
B8: Additional
B9: Additional
B10: Additional
B11: Additional
B12: Additional
B13: Additional
B14: Additional
B15: Additional
B16: Additional
... B22: Additional
B23: Total Value of the Month | C23: =SUM(C3:C22) -> 0 | D23: =SUM(D3:D22) -> 0 | E23: =SUM(E3:E22) -> 0 | F23: =SUM(F3:F22) -> 47139.85 | G23: =SUM(G3:G22) -> 29472.98 | H23: =SUM(H3:H22) -> 39194.79 | I23: =SUM(I3:I22) -> 0 | J23: =SUM(J3:J22) -> 0 | ... BA23: =SUM(BA3:BA22) -> 0
C24: Note: | D24: Copy the Amount, Right Click and selete value(123)

Sheet Sheet5
D13: Note: | E13: Copy the Amount, Right Click and selete value(123)
